<?xml version="1.0"?>
<robot xmlns:xacro="http://www.ros.org/wiki/xacro" name="arduinobot">

    <xacro:property name="PI" value="3.14159"/>

    <material name="dark_green">
      <color rgba="0 0.5 0 1"/>
    </material>

    <material name="white">
      <color rgba="1 1 1 1" />
    </material>

    <material name="black">
      <color rgba="0 0 0 1" />
    </material>

    <link name="world"/>

    <link name="base_link">

    <inertial>
      <origin
        xyz="4.1633E-17 0 0.073876"
        rpy="0 0 0" />
      <mass
        value="17.147" />
      <inertia
        ixx="0.192"
        ixy="-4.9423E-10"
        ixz="1.2752E-17"
        iyy="0.192"
        iyz="2.6417E-18"
        izz="0.29544" />
    </inertial>

        <visual>
            <origin rpy="0 0 0" xyz="0 0 0"/>
            <geometry>
                <mesh filename="package://arduinobot_description/meshes/base_plate.STL"/>
            </geometry>
            <material name="dark_green"/>
        </visual>
        <collision>
            <origin rpy="0 0 0" xyz="0 0 0"/>
            <geometry>
                <mesh filename="package://arduinobot_description/meshes/base_plate.STL"/>
            </geometry>
        </collision>
    </link>
 
    <joint name="virtual_joint" type="fixed">
        <parent link="world"/>
        <child link="base_link"/>
        <origin xyz="0 0 0" rpy="0 0 0"/>
    </joint> 

    <link name="link_1">

      <inertial>
        <origin
          xyz="-2.5757E-14 0.11047 -7.8988E-11"
          rpy="0 0 0" />
        <mass
          value="3.0905" />
        <inertia
          ixx="0.026302"
          ixy="-2.5267E-15"
          ixz="-1.4177E-12"
          iyy="0.019632"
          iyz="-7.4535E-12"
          izz="0.025388" />
      </inertial>
      
        <visual>
            <origin rpy="0 0 0" xyz="0 0 0"/>
            <geometry>
                <mesh filename="package://arduinobot_description/meshes/link_1.STL"/>
            </geometry>
            <material name="dark_green"/>
        </visual>

        <collision>
          <origin rpy="0 0 0" xyz="0 0 0"/>
          <geometry>
              <mesh filename="package://arduinobot_description/meshes/link_1.STL"/>
          </geometry>
      </collision>

    </link>

    <joint name="joint_1" type="revolute">
        <parent link="base_link"/>
        <child link="link_1"/>
        <axis xyz="0 1 0"/>
        <origin xyz="0 0 0.2" rpy="1.5708 0 1.5708"/>
        <limit lower="0" upper="6.284" effort="300" velocity="10"/>
    </joint> 

    <link name="link_2">

      <inertial>
        <origin
          xyz="-1.1102E-16 0.16752 -2.498E-16"
          rpy="0 0 0" />
        <mass
          value="5.5867" />
        <inertia
          ixx="0.12632"
          ixy="8.4877E-17"
          ixz="7.8685E-19"
          iyy="0.011401"
          iyz="1.4432E-16"
          izz="0.12911" />
        </inertial>
      <visual>
          <origin rpy="0 0 0" xyz="0 0 0"/>
          <geometry>
              <mesh filename="package://arduinobot_description/meshes/link_2.STL"/>
          </geometry>
          <material name="dark_green"/>
      </visual>

      <collision>
        <origin rpy="0 0 0" xyz="0 0 0"/>
        <geometry>
            <mesh filename="package://arduinobot_description/meshes/link_2.STL"/>
        </geometry>
      </collision>
    </link>

    <joint name="joint_2" type="revolute">
        <parent link="link_1"/>
        <child link="link_2"/>
        <axis xyz="0 0 1"/>
        <origin xyz="0 0.205 0" rpy="0 0 0"/>
        <limit lower="-1.57" upper="1.57" effort="300" velocity="10"/>
    </joint> 

    <link name="link_3">

      <inertial>
      <origin
        xyz="-0.17893 0 -1.249E-16"
        rpy="0 0 0" />
      <mass
        value="2.8262" />
      <inertia
        ixx="0.0074041"
        ixy="-1.7927E-17"
        ixz="4.2672E-17"
        iyy="0.028552"
        iyz="-3.4736E-10"
        izz="0.025128" />
      </inertial>
      <visual>
          <origin rpy="0 0 0" xyz="0 0 0"/>
          <geometry>
              <mesh filename="package://arduinobot_description/meshes/link_3.STL"/>
          </geometry>
          <material name="dark_green"/>
      </visual>

      <collision>
        <origin rpy="0 0 0" xyz="0 0 0"/>
        <geometry>
            <mesh filename="package://arduinobot_description/meshes/link_3.STL"/>
        </geometry>
      </collision>
    </link>

    <joint name="joint_3" type="revolute">
        <parent link="link_2"/>
        <child link="link_3"/>
        <axis xyz="0 0 1"/>
        <origin xyz="0 0.4 0" rpy="0 0 0"/>
        <limit lower="-4.3284" upper="1.157" effort="300" velocity="10"/>
    </joint> 

    <link name="link_4">

      <inertial>
        <origin
          xyz="-0.051672 -2.2204E-16 -1.1102E-16"
          rpy="0 0 0" />
        <mass
          value="1.8097" />
        <inertia
          ixx="0.0023112"
          ixy="-9.6437E-18"
          ixz="-9.9829E-19"
          iyy="0.0096102"
          iyz="1.3194E-19"
          izz="0.0093908" />
      </inertial>

      <visual>
          <origin rpy="0 0 0" xyz="0 0 0"/>
          <geometry>
              <mesh filename="package://arduinobot_description/meshes/link_4.STL"/>
          </geometry>
          <material name="dark_green"/>
      </visual>
      <collision>
        <origin rpy="0 0 0" xyz="0 0 0"/>
        <geometry>
            <mesh filename="package://arduinobot_description/meshes/link_4.STL"/>
        </geometry>
      </collision>
    </link>

    <joint name="joint_4" type="revolute">
        <parent link="link_3"/>
        <child link="link_4"/>
        <axis xyz="0 0 1"/>
        <origin xyz="-0.35 0 0" rpy="0 0 1.5708"/>
        <limit lower="-3.142" upper="0" effort="200" velocity="10" />
    </joint> 

    <link name="link_5">

      <inertial>
      <origin
        xyz="-0.018544 0 -2.7756E-17"
        rpy="0 0 0" />
      <mass
        value="0.19053" />
      <inertia
        ixx="0.00030197"
        ixy="1.6611E-20"
        ixz="3.6309E-21"
        iyy="0.00022817"
        iyz="-1.9664E-11"
        izz="0.00011843" />
      </inertial>

      <visual>
          <origin rpy="0 0 0" xyz="0 0 0"/>
          <geometry>
              <mesh filename="package://arduinobot_description/meshes/link_5.STL"/>
          </geometry>
          <material name="dark_green"/>
      </visual>
      <collision>
        <origin rpy="0 0 0" xyz="0 0 0"/>
        <geometry>
            <mesh filename="package://arduinobot_description/meshes/link_5.STL"/>
        </geometry>
      </collision>
    </link>

    <joint name="joint_5" type="revolute">
        <parent link="link_4"/>
        <child link="link_5"/>
        <axis xyz="1 0 0"/>
        <origin xyz="-0.188 0 0" rpy="0 0 0"/>
        <limit lower="0" upper="3.142" effort="200" velocity="10" />
    </joint> 

    <link name="link_6">

      <inertial>
        <origin
          xyz="-0.60237 0.4 -0.016013"
          rpy="0 0 0" />
        <mass
          value="0.11653" />
        <inertia
          ixx="3.9246E-05"
          ixy="-9.4878E-20"
          ixz="1.0258E-05"
          iyy="7.1189E-05"
          iyz="-3.4206E-20"
          izz="8.4875E-05" />
      </inertial>

      <visual>
          <origin rpy="0 0 0" xyz="0 0 0"/>
          <geometry>
              <mesh filename="package://arduinobot_description/meshes/link_6.STL"/>
          </geometry>
          <material name="white"/>
      </visual>
      <collision>
        <origin rpy="0 0 0" xyz="0 0 0"/>
        <geometry>
            <mesh filename="package://arduinobot_description/meshes/link_6.STL"/>
        </geometry>
    </collision>
    </link>

    <joint name="joint_6" type="prismatic">
        <parent link="link_5"/>
        <child link="link_6"/>
        <axis xyz="0 0 -1"/>
        <origin xyz="0.54 -0.4 0" rpy="0 0 0"/>
        <limit lower="0" upper="0.055" effort="100" velocity="10" />
    </joint> 

    <link name="link_7">

      <inertial>
        <origin
          xyz="-0.60237 0.4 -0.016013"
          rpy="0 0 0" />
        <mass
          value="0.11653" />
        <inertia
          ixx="3.9246E-05"
          ixy="-4.7946E-20"
          ixz="1.0258E-05"
          iyy="7.1189E-05"
          iyz="-3.946E-20"
          izz="8.4875E-05" />
      </inertial>

      <visual>
          <origin rpy="0 0 0" xyz="0 0 0"/>
          <geometry>
              <mesh filename="package://arduinobot_description/meshes/link_7.STL"/>
          </geometry>
          <material name="white"/>
      </visual>
      <collision>
        <origin rpy="0 0 0" xyz="0 0 0"/>
        <geometry>
            <mesh filename="package://arduinobot_description/meshes/link_7.STL"/>
        </geometry>
    </collision>
    </link>

    <joint name="joint_7" type="prismatic">
        <parent link="link_5"/>
        <child link="link_7"/>
        <axis xyz="0 0 1"/>
        <origin xyz="0.54 0.4 0" rpy="3.1416 0 0"/>
        <limit lower="-0.055" upper="0" effort="100" velocity="10" />
    </joint> 


</robot>